[2022-11-15 16:33:30,479] {taskinstance.py:1179} INFO - Dependencies all met for <TaskInstance: DAG_Minio_S3_Wait_for_File.S3BucketSensorNewFiles manual__2022-11-15T16:33:22.187266+00:00 [queued]>
[2022-11-15 16:33:30,619] {taskinstance.py:1179} INFO - Dependencies all met for <TaskInstance: DAG_Minio_S3_Wait_for_File.S3BucketSensorNewFiles manual__2022-11-15T16:33:22.187266+00:00 [queued]>
[2022-11-15 16:33:30,628] {taskinstance.py:1376} INFO - 
--------------------------------------------------------------------------------
[2022-11-15 16:33:30,631] {taskinstance.py:1377} INFO - Starting attempt 1 of 6
[2022-11-15 16:33:30,633] {taskinstance.py:1378} INFO - 
--------------------------------------------------------------------------------
[2022-11-15 16:33:30,925] {taskinstance.py:1397} INFO - Executing <Task(S3KeySensor): S3BucketSensorNewFiles> on 2022-11-15 16:33:22.187266+00:00
[2022-11-15 16:33:30,977] {standard_task_runner.py:52} INFO - Started process 416 to run task
[2022-11-15 16:33:31,011] {standard_task_runner.py:79} INFO - Running: ['***', 'tasks', 'run', 'DAG_Minio_S3_Wait_for_File', 'S3BucketSensorNewFiles', 'manual__2022-11-15T16:33:22.187266+00:00', '--job-id', '9', '--raw', '--subdir', 'DAGS_FOLDER/sensor.py', '--cfg-path', '/tmp/tmp8er1bpsw', '--error-file', '/tmp/tmpa7nz4to4']
[2022-11-15 16:33:31,018] {standard_task_runner.py:80} INFO - Job 9: Subtask S3BucketSensorNewFiles
[2022-11-15 16:33:31,568] {task_command.py:371} INFO - Running <TaskInstance: DAG_Minio_S3_Wait_for_File.S3BucketSensorNewFiles manual__2022-11-15T16:33:22.187266+00:00 [running]> on host 73a41ac08797
[2022-11-15 16:33:32,342] {taskinstance.py:1591} INFO - Exporting the following env vars:
AIRFLOW_CTX_DAG_OWNER=Maico Bernal
AIRFLOW_CTX_DAG_ID=DAG_Minio_S3_Wait_for_File
AIRFLOW_CTX_TASK_ID=S3BucketSensorNewFiles
AIRFLOW_CTX_EXECUTION_DATE=2022-11-15T16:33:22.187266+00:00
AIRFLOW_CTX_TRY_NUMBER=1
AIRFLOW_CTX_DAG_RUN_ID=manual__2022-11-15T16:33:22.187266+00:00
[2022-11-15 16:33:32,384] {s3.py:104} INFO - Poking for key : s3://data/precio*
[2022-11-15 16:33:32,510] {base.py:68} INFO - Using connection ID 'minio_conn' for task execution.
[2022-11-15 16:33:32,541] {base_aws.py:210} INFO - Credentials retrieved from extra_config
[2022-11-15 16:33:33,896] {taskinstance.py:1909} ERROR - Task failed with exception
Traceback (most recent call last):
  File "/home/airflow/.local/lib/python3.7/site-packages/airflow/sensors/base.py", line 277, in execute
    poke_return = self.poke(context)
  File "/home/airflow/.local/lib/python3.7/site-packages/airflow/providers/amazon/aws/sensors/s3.py", line 133, in poke
    return all(self._check_key(key) for key in self.bucket_key)
  File "/home/airflow/.local/lib/python3.7/site-packages/airflow/providers/amazon/aws/sensors/s3.py", line 133, in <genexpr>
    return all(self._check_key(key) for key in self.bucket_key)
  File "/home/airflow/.local/lib/python3.7/site-packages/airflow/providers/amazon/aws/sensors/s3.py", line 115, in _check_key
    files = self.get_hook().get_file_metadata(prefix, bucket_name)
  File "/home/airflow/.local/lib/python3.7/site-packages/airflow/providers/amazon/aws/hooks/s3.py", line 63, in wrapper
    return func(*bound_args.args, **bound_args.kwargs)
  File "/home/airflow/.local/lib/python3.7/site-packages/airflow/providers/amazon/aws/hooks/s3.py", line 403, in get_file_metadata
    for page in response:
  File "/home/airflow/.local/lib/python3.7/site-packages/botocore/paginate.py", line 269, in __iter__
    response = self._make_request(current_kwargs)
  File "/home/airflow/.local/lib/python3.7/site-packages/botocore/paginate.py", line 357, in _make_request
    return self._method(**current_kwargs)
  File "/home/airflow/.local/lib/python3.7/site-packages/botocore/client.py", line 508, in _api_call
    return self._make_api_call(operation_name, kwargs)
  File "/home/airflow/.local/lib/python3.7/site-packages/botocore/client.py", line 915, in _make_api_call
    raise error_class(parsed_response, operation_name)
botocore.exceptions.ClientError: An error occurred (InvalidAccessKeyId) when calling the ListObjectsV2 operation: The Access Key Id you provided does not exist in our records.
[2022-11-15 16:33:34,024] {taskinstance.py:1420} INFO - Marking task as UP_FOR_RETRY. dag_id=DAG_Minio_S3_Wait_for_File, task_id=S3BucketSensorNewFiles, execution_date=20221115T163322, start_date=20221115T163330, end_date=20221115T163334
[2022-11-15 16:33:34,631] {standard_task_runner.py:97} ERROR - Failed to execute job 9 for task S3BucketSensorNewFiles (An error occurred (InvalidAccessKeyId) when calling the ListObjectsV2 operation: The Access Key Id you provided does not exist in our records.; 416)
[2022-11-15 16:33:34,851] {local_task_job.py:156} INFO - Task exited with return code 1
[2022-11-15 16:33:35,267] {local_task_job.py:273} INFO - 0 downstream tasks scheduled from follow-on schedule check
